{
 "cells": [
  {
   "cell_type": "code",
   "execution_count": 3,
   "metadata": {},
   "outputs": [],
   "source": [
    "from langchain.chat_models import ChatOpenAI\n",
    "from langchain.schema import HumanMessage,SystemMessage\n",
    "from langchain.prompts.chat import ChatPromptTemplate,HumanMessagePromptTemplate,SystemMessagePromptTemplate"
   ]
  },
  {
   "cell_type": "code",
   "execution_count": 5,
   "metadata": {},
   "outputs": [
    {
     "name": "stderr",
     "output_type": "stream",
     "text": [
      "WARNING! top_p is not default parameter.\n",
      "                    top_p was transferred to model_kwargs.\n",
      "                    Please confirm that top_p is what you intended.\n",
      "WARNING! frequency_penalty is not default parameter.\n",
      "                    frequency_penalty was transferred to model_kwargs.\n",
      "                    Please confirm that frequency_penalty is what you intended.\n",
      "WARNING! presence_penalty is not default parameter.\n",
      "                    presence_penalty was transferred to model_kwargs.\n",
      "                    Please confirm that presence_penalty is what you intended.\n"
     ]
    }
   ],
   "source": [
    "chat = ChatOpenAI(model='gpt-3.5-turbo-1106',\n",
    "                temperature=1,\n",
    "                max_tokens=4095,\n",
    "                top_p=1,\n",
    "                frequency_penalty=0,\n",
    "                presence_penalty=0)"
   ]
  },
  {
   "cell_type": "code",
   "execution_count": 7,
   "metadata": {},
   "outputs": [],
   "source": [
    "system_content =\"\"\"\n",
    "你是中国铁路专家，尤其擅长《铁路旅客运输规程》内容。\n",
    "\n",
    "接下来，你收到的都是关于《铁路旅客运输规程》的内容，你需要整理成问答格式，并生成大模型训练的内容和格式。\n",
    "\n",
    "示例输入：\n",
    "\n",
    "第四条 车票是铁路旅客运输合同的凭证，可以采取纸质形式或者电子数据形式，一般应当载明发站、到站、车次、车厢号、席别、席位号、票价、开车时间等主要信息。铁路运输企业与旅客另有约定的，按照其约定。\n",
    "\n",
    "期待结果：\n",
    "\n",
    "content:\"什么是车票？\"\n",
    "summary:\"车票是铁路旅客运输合同的凭证，可以采取纸质形式或者电子数据形式，一般应当载明发站、到站、车次、车厢号、席别、席位号、票价、开车时间等主要信息。铁路运输企业与旅客另有约定的，按照其约定。\"\n",
    "\n",
    "content:\"车票包括哪些信息？\"\n",
    "summary:\"车票包括发站、到站、车次、车厢号、席别、席位号、票价、开车时间等主要信息\"\n",
    "\"\"\""
   ]
  },
  {
   "cell_type": "code",
   "execution_count": 8,
   "metadata": {},
   "outputs": [],
   "source": [
    "raw_content = \"第五条 铁路运输企业应当提供方便快捷的票务服务，为旅客提供良好的旅行环境和服务设施，文明礼貌地为旅客服务，在约定期限或者合理期限内将旅客安全运输到车票载明的到站。\""
   ]
  },
  {
   "cell_type": "code",
   "execution_count": 9,
   "metadata": {},
   "outputs": [],
   "source": [
    "messages = [\n",
    "    SystemMessage(\n",
    "        content=system_content\n",
    "    ),\n",
    "    HumanMessage(\n",
    "        content=raw_content\n",
    "    ),\n",
    "]"
   ]
  },
  {
   "cell_type": "code",
   "execution_count": 15,
   "metadata": {},
   "outputs": [
    {
     "ename": "APIConnectionError",
     "evalue": "Connection error.",
     "output_type": "error",
     "traceback": [
      "\u001b[0;31m---------------------------------------------------------------------------\u001b[0m",
      "\u001b[0;31mgaierror\u001b[0m                                  Traceback (most recent call last)",
      "File \u001b[0;32m~/anaconda3/envs/llm4/lib/python3.9/site-packages/httpcore/_exceptions.py:10\u001b[0m, in \u001b[0;36mmap_exceptions\u001b[0;34m(map)\u001b[0m\n\u001b[1;32m      9\u001b[0m \u001b[39mtry\u001b[39;00m:\n\u001b[0;32m---> 10\u001b[0m     \u001b[39myield\u001b[39;00m\n\u001b[1;32m     11\u001b[0m \u001b[39mexcept\u001b[39;00m \u001b[39mException\u001b[39;00m \u001b[39mas\u001b[39;00m exc:  \u001b[39m# noqa: PIE786\u001b[39;00m\n",
      "File \u001b[0;32m~/anaconda3/envs/llm4/lib/python3.9/site-packages/httpcore/_backends/sync.py:206\u001b[0m, in \u001b[0;36mSyncBackend.connect_tcp\u001b[0;34m(self, host, port, timeout, local_address, socket_options)\u001b[0m\n\u001b[1;32m    205\u001b[0m \u001b[39mwith\u001b[39;00m map_exceptions(exc_map):\n\u001b[0;32m--> 206\u001b[0m     sock \u001b[39m=\u001b[39m socket\u001b[39m.\u001b[39;49mcreate_connection(\n\u001b[1;32m    207\u001b[0m         address,\n\u001b[1;32m    208\u001b[0m         timeout,\n\u001b[1;32m    209\u001b[0m         source_address\u001b[39m=\u001b[39;49msource_address,\n\u001b[1;32m    210\u001b[0m     )\n\u001b[1;32m    211\u001b[0m     \u001b[39mfor\u001b[39;00m option \u001b[39min\u001b[39;00m socket_options:\n",
      "File \u001b[0;32m~/anaconda3/envs/llm4/lib/python3.9/socket.py:823\u001b[0m, in \u001b[0;36mcreate_connection\u001b[0;34m(address, timeout, source_address)\u001b[0m\n\u001b[1;32m    822\u001b[0m err \u001b[39m=\u001b[39m \u001b[39mNone\u001b[39;00m\n\u001b[0;32m--> 823\u001b[0m \u001b[39mfor\u001b[39;00m res \u001b[39min\u001b[39;00m getaddrinfo(host, port, \u001b[39m0\u001b[39;49m, SOCK_STREAM):\n\u001b[1;32m    824\u001b[0m     af, socktype, proto, canonname, sa \u001b[39m=\u001b[39m res\n",
      "File \u001b[0;32m~/anaconda3/envs/llm4/lib/python3.9/socket.py:954\u001b[0m, in \u001b[0;36mgetaddrinfo\u001b[0;34m(host, port, family, type, proto, flags)\u001b[0m\n\u001b[1;32m    953\u001b[0m addrlist \u001b[39m=\u001b[39m []\n\u001b[0;32m--> 954\u001b[0m \u001b[39mfor\u001b[39;00m res \u001b[39min\u001b[39;00m _socket\u001b[39m.\u001b[39;49mgetaddrinfo(host, port, family, \u001b[39mtype\u001b[39;49m, proto, flags):\n\u001b[1;32m    955\u001b[0m     af, socktype, proto, canonname, sa \u001b[39m=\u001b[39m res\n",
      "\u001b[0;31mgaierror\u001b[0m: [Errno -3] Temporary failure in name resolution",
      "\nThe above exception was the direct cause of the following exception:\n",
      "\u001b[0;31mConnectError\u001b[0m                              Traceback (most recent call last)",
      "File \u001b[0;32m~/anaconda3/envs/llm4/lib/python3.9/site-packages/httpx/_transports/default.py:67\u001b[0m, in \u001b[0;36mmap_httpcore_exceptions\u001b[0;34m()\u001b[0m\n\u001b[1;32m     66\u001b[0m \u001b[39mtry\u001b[39;00m:\n\u001b[0;32m---> 67\u001b[0m     \u001b[39myield\u001b[39;00m\n\u001b[1;32m     68\u001b[0m \u001b[39mexcept\u001b[39;00m \u001b[39mException\u001b[39;00m \u001b[39mas\u001b[39;00m exc:\n",
      "File \u001b[0;32m~/anaconda3/envs/llm4/lib/python3.9/site-packages/httpx/_transports/default.py:231\u001b[0m, in \u001b[0;36mHTTPTransport.handle_request\u001b[0;34m(self, request)\u001b[0m\n\u001b[1;32m    230\u001b[0m \u001b[39mwith\u001b[39;00m map_httpcore_exceptions():\n\u001b[0;32m--> 231\u001b[0m     resp \u001b[39m=\u001b[39m \u001b[39mself\u001b[39;49m\u001b[39m.\u001b[39;49m_pool\u001b[39m.\u001b[39;49mhandle_request(req)\n\u001b[1;32m    233\u001b[0m \u001b[39massert\u001b[39;00m \u001b[39misinstance\u001b[39m(resp\u001b[39m.\u001b[39mstream, typing\u001b[39m.\u001b[39mIterable)\n",
      "File \u001b[0;32m~/anaconda3/envs/llm4/lib/python3.9/site-packages/httpcore/_sync/connection_pool.py:268\u001b[0m, in \u001b[0;36mConnectionPool.handle_request\u001b[0;34m(self, request)\u001b[0m\n\u001b[1;32m    267\u001b[0m         \u001b[39mself\u001b[39m\u001b[39m.\u001b[39mresponse_closed(status)\n\u001b[0;32m--> 268\u001b[0m     \u001b[39mraise\u001b[39;00m exc\n\u001b[1;32m    269\u001b[0m \u001b[39melse\u001b[39;00m:\n",
      "File \u001b[0;32m~/anaconda3/envs/llm4/lib/python3.9/site-packages/httpcore/_sync/connection_pool.py:251\u001b[0m, in \u001b[0;36mConnectionPool.handle_request\u001b[0;34m(self, request)\u001b[0m\n\u001b[1;32m    250\u001b[0m \u001b[39mtry\u001b[39;00m:\n\u001b[0;32m--> 251\u001b[0m     response \u001b[39m=\u001b[39m connection\u001b[39m.\u001b[39;49mhandle_request(request)\n\u001b[1;32m    252\u001b[0m \u001b[39mexcept\u001b[39;00m ConnectionNotAvailable:\n\u001b[1;32m    253\u001b[0m     \u001b[39m# The ConnectionNotAvailable exception is a special case, that\u001b[39;00m\n\u001b[1;32m    254\u001b[0m     \u001b[39m# indicates we need to retry the request on a new connection.\u001b[39;00m\n\u001b[0;32m   (...)\u001b[0m\n\u001b[1;32m    258\u001b[0m     \u001b[39m# might end up as an HTTP/2 connection, but which actually ends\u001b[39;00m\n\u001b[1;32m    259\u001b[0m     \u001b[39m# up as HTTP/1.1.\u001b[39;00m\n",
      "File \u001b[0;32m~/anaconda3/envs/llm4/lib/python3.9/site-packages/httpcore/_sync/connection.py:99\u001b[0m, in \u001b[0;36mHTTPConnection.handle_request\u001b[0;34m(self, request)\u001b[0m\n\u001b[1;32m     98\u001b[0m         \u001b[39mself\u001b[39m\u001b[39m.\u001b[39m_connect_failed \u001b[39m=\u001b[39m \u001b[39mTrue\u001b[39;00m\n\u001b[0;32m---> 99\u001b[0m         \u001b[39mraise\u001b[39;00m exc\n\u001b[1;32m    100\u001b[0m \u001b[39melif\u001b[39;00m \u001b[39mnot\u001b[39;00m \u001b[39mself\u001b[39m\u001b[39m.\u001b[39m_connection\u001b[39m.\u001b[39mis_available():\n",
      "File \u001b[0;32m~/anaconda3/envs/llm4/lib/python3.9/site-packages/httpcore/_sync/connection.py:76\u001b[0m, in \u001b[0;36mHTTPConnection.handle_request\u001b[0;34m(self, request)\u001b[0m\n\u001b[1;32m     75\u001b[0m \u001b[39mtry\u001b[39;00m:\n\u001b[0;32m---> 76\u001b[0m     stream \u001b[39m=\u001b[39m \u001b[39mself\u001b[39;49m\u001b[39m.\u001b[39;49m_connect(request)\n\u001b[1;32m     78\u001b[0m     ssl_object \u001b[39m=\u001b[39m stream\u001b[39m.\u001b[39mget_extra_info(\u001b[39m\"\u001b[39m\u001b[39mssl_object\u001b[39m\u001b[39m\"\u001b[39m)\n",
      "File \u001b[0;32m~/anaconda3/envs/llm4/lib/python3.9/site-packages/httpcore/_sync/connection.py:124\u001b[0m, in \u001b[0;36mHTTPConnection._connect\u001b[0;34m(self, request)\u001b[0m\n\u001b[1;32m    123\u001b[0m \u001b[39mwith\u001b[39;00m Trace(\u001b[39m\"\u001b[39m\u001b[39mconnect_tcp\u001b[39m\u001b[39m\"\u001b[39m, logger, request, kwargs) \u001b[39mas\u001b[39;00m trace:\n\u001b[0;32m--> 124\u001b[0m     stream \u001b[39m=\u001b[39m \u001b[39mself\u001b[39;49m\u001b[39m.\u001b[39;49m_network_backend\u001b[39m.\u001b[39;49mconnect_tcp(\u001b[39m*\u001b[39;49m\u001b[39m*\u001b[39;49mkwargs)\n\u001b[1;32m    125\u001b[0m     trace\u001b[39m.\u001b[39mreturn_value \u001b[39m=\u001b[39m stream\n",
      "File \u001b[0;32m~/anaconda3/envs/llm4/lib/python3.9/site-packages/httpcore/_backends/sync.py:213\u001b[0m, in \u001b[0;36mSyncBackend.connect_tcp\u001b[0;34m(self, host, port, timeout, local_address, socket_options)\u001b[0m\n\u001b[1;32m    212\u001b[0m         sock\u001b[39m.\u001b[39msetsockopt(\u001b[39m*\u001b[39moption)  \u001b[39m# pragma: no cover\u001b[39;00m\n\u001b[0;32m--> 213\u001b[0m     sock\u001b[39m.\u001b[39msetsockopt(socket\u001b[39m.\u001b[39mIPPROTO_TCP, socket\u001b[39m.\u001b[39mTCP_NODELAY, \u001b[39m1\u001b[39m)\n\u001b[1;32m    214\u001b[0m \u001b[39mreturn\u001b[39;00m SyncStream(sock)\n",
      "File \u001b[0;32m~/anaconda3/envs/llm4/lib/python3.9/contextlib.py:137\u001b[0m, in \u001b[0;36m_GeneratorContextManager.__exit__\u001b[0;34m(self, typ, value, traceback)\u001b[0m\n\u001b[1;32m    136\u001b[0m \u001b[39mtry\u001b[39;00m:\n\u001b[0;32m--> 137\u001b[0m     \u001b[39mself\u001b[39;49m\u001b[39m.\u001b[39;49mgen\u001b[39m.\u001b[39;49mthrow(typ, value, traceback)\n\u001b[1;32m    138\u001b[0m \u001b[39mexcept\u001b[39;00m \u001b[39mStopIteration\u001b[39;00m \u001b[39mas\u001b[39;00m exc:\n\u001b[1;32m    139\u001b[0m     \u001b[39m# Suppress StopIteration *unless* it's the same exception that\u001b[39;00m\n\u001b[1;32m    140\u001b[0m     \u001b[39m# was passed to throw().  This prevents a StopIteration\u001b[39;00m\n\u001b[1;32m    141\u001b[0m     \u001b[39m# raised inside the \"with\" statement from being suppressed.\u001b[39;00m\n",
      "File \u001b[0;32m~/anaconda3/envs/llm4/lib/python3.9/site-packages/httpcore/_exceptions.py:14\u001b[0m, in \u001b[0;36mmap_exceptions\u001b[0;34m(map)\u001b[0m\n\u001b[1;32m     13\u001b[0m     \u001b[39mif\u001b[39;00m \u001b[39misinstance\u001b[39m(exc, from_exc):\n\u001b[0;32m---> 14\u001b[0m         \u001b[39mraise\u001b[39;00m to_exc(exc) \u001b[39mfrom\u001b[39;00m \u001b[39mexc\u001b[39;00m\n\u001b[1;32m     15\u001b[0m \u001b[39mraise\u001b[39;00m\n",
      "\u001b[0;31mConnectError\u001b[0m: [Errno -3] Temporary failure in name resolution",
      "\nThe above exception was the direct cause of the following exception:\n",
      "\u001b[0;31mConnectError\u001b[0m                              Traceback (most recent call last)",
      "File \u001b[0;32m~/anaconda3/envs/llm4/lib/python3.9/site-packages/openai/_base_client.py:918\u001b[0m, in \u001b[0;36mSyncAPIClient._request\u001b[0;34m(self, cast_to, options, remaining_retries, stream, stream_cls)\u001b[0m\n\u001b[1;32m    917\u001b[0m \u001b[39mtry\u001b[39;00m:\n\u001b[0;32m--> 918\u001b[0m     response \u001b[39m=\u001b[39m \u001b[39mself\u001b[39;49m\u001b[39m.\u001b[39;49m_client\u001b[39m.\u001b[39;49msend(\n\u001b[1;32m    919\u001b[0m         request,\n\u001b[1;32m    920\u001b[0m         stream\u001b[39m=\u001b[39;49mstream \u001b[39mor\u001b[39;49;00m \u001b[39mself\u001b[39;49m\u001b[39m.\u001b[39;49m_should_stream_response_body(request\u001b[39m=\u001b[39;49mrequest),\n\u001b[1;32m    921\u001b[0m         \u001b[39m*\u001b[39;49m\u001b[39m*\u001b[39;49mkwargs,\n\u001b[1;32m    922\u001b[0m     )\n\u001b[1;32m    923\u001b[0m \u001b[39mexcept\u001b[39;00m httpx\u001b[39m.\u001b[39mTimeoutException \u001b[39mas\u001b[39;00m err:\n",
      "File \u001b[0;32m~/anaconda3/envs/llm4/lib/python3.9/site-packages/httpx/_client.py:915\u001b[0m, in \u001b[0;36mClient.send\u001b[0;34m(self, request, stream, auth, follow_redirects)\u001b[0m\n\u001b[1;32m    913\u001b[0m auth \u001b[39m=\u001b[39m \u001b[39mself\u001b[39m\u001b[39m.\u001b[39m_build_request_auth(request, auth)\n\u001b[0;32m--> 915\u001b[0m response \u001b[39m=\u001b[39m \u001b[39mself\u001b[39;49m\u001b[39m.\u001b[39;49m_send_handling_auth(\n\u001b[1;32m    916\u001b[0m     request,\n\u001b[1;32m    917\u001b[0m     auth\u001b[39m=\u001b[39;49mauth,\n\u001b[1;32m    918\u001b[0m     follow_redirects\u001b[39m=\u001b[39;49mfollow_redirects,\n\u001b[1;32m    919\u001b[0m     history\u001b[39m=\u001b[39;49m[],\n\u001b[1;32m    920\u001b[0m )\n\u001b[1;32m    921\u001b[0m \u001b[39mtry\u001b[39;00m:\n",
      "File \u001b[0;32m~/anaconda3/envs/llm4/lib/python3.9/site-packages/httpx/_client.py:943\u001b[0m, in \u001b[0;36mClient._send_handling_auth\u001b[0;34m(self, request, auth, follow_redirects, history)\u001b[0m\n\u001b[1;32m    942\u001b[0m \u001b[39mwhile\u001b[39;00m \u001b[39mTrue\u001b[39;00m:\n\u001b[0;32m--> 943\u001b[0m     response \u001b[39m=\u001b[39m \u001b[39mself\u001b[39;49m\u001b[39m.\u001b[39;49m_send_handling_redirects(\n\u001b[1;32m    944\u001b[0m         request,\n\u001b[1;32m    945\u001b[0m         follow_redirects\u001b[39m=\u001b[39;49mfollow_redirects,\n\u001b[1;32m    946\u001b[0m         history\u001b[39m=\u001b[39;49mhistory,\n\u001b[1;32m    947\u001b[0m     )\n\u001b[1;32m    948\u001b[0m     \u001b[39mtry\u001b[39;00m:\n",
      "File \u001b[0;32m~/anaconda3/envs/llm4/lib/python3.9/site-packages/httpx/_client.py:980\u001b[0m, in \u001b[0;36mClient._send_handling_redirects\u001b[0;34m(self, request, follow_redirects, history)\u001b[0m\n\u001b[1;32m    978\u001b[0m     hook(request)\n\u001b[0;32m--> 980\u001b[0m response \u001b[39m=\u001b[39m \u001b[39mself\u001b[39;49m\u001b[39m.\u001b[39;49m_send_single_request(request)\n\u001b[1;32m    981\u001b[0m \u001b[39mtry\u001b[39;00m:\n",
      "File \u001b[0;32m~/anaconda3/envs/llm4/lib/python3.9/site-packages/httpx/_client.py:1016\u001b[0m, in \u001b[0;36mClient._send_single_request\u001b[0;34m(self, request)\u001b[0m\n\u001b[1;32m   1015\u001b[0m \u001b[39mwith\u001b[39;00m request_context(request\u001b[39m=\u001b[39mrequest):\n\u001b[0;32m-> 1016\u001b[0m     response \u001b[39m=\u001b[39m transport\u001b[39m.\u001b[39;49mhandle_request(request)\n\u001b[1;32m   1018\u001b[0m \u001b[39massert\u001b[39;00m \u001b[39misinstance\u001b[39m(response\u001b[39m.\u001b[39mstream, SyncByteStream)\n",
      "File \u001b[0;32m~/anaconda3/envs/llm4/lib/python3.9/site-packages/httpx/_transports/default.py:231\u001b[0m, in \u001b[0;36mHTTPTransport.handle_request\u001b[0;34m(self, request)\u001b[0m\n\u001b[1;32m    230\u001b[0m \u001b[39mwith\u001b[39;00m map_httpcore_exceptions():\n\u001b[0;32m--> 231\u001b[0m     resp \u001b[39m=\u001b[39m \u001b[39mself\u001b[39m\u001b[39m.\u001b[39m_pool\u001b[39m.\u001b[39mhandle_request(req)\n\u001b[1;32m    233\u001b[0m \u001b[39massert\u001b[39;00m \u001b[39misinstance\u001b[39m(resp\u001b[39m.\u001b[39mstream, typing\u001b[39m.\u001b[39mIterable)\n",
      "File \u001b[0;32m~/anaconda3/envs/llm4/lib/python3.9/contextlib.py:137\u001b[0m, in \u001b[0;36m_GeneratorContextManager.__exit__\u001b[0;34m(self, typ, value, traceback)\u001b[0m\n\u001b[1;32m    136\u001b[0m \u001b[39mtry\u001b[39;00m:\n\u001b[0;32m--> 137\u001b[0m     \u001b[39mself\u001b[39;49m\u001b[39m.\u001b[39;49mgen\u001b[39m.\u001b[39;49mthrow(typ, value, traceback)\n\u001b[1;32m    138\u001b[0m \u001b[39mexcept\u001b[39;00m \u001b[39mStopIteration\u001b[39;00m \u001b[39mas\u001b[39;00m exc:\n\u001b[1;32m    139\u001b[0m     \u001b[39m# Suppress StopIteration *unless* it's the same exception that\u001b[39;00m\n\u001b[1;32m    140\u001b[0m     \u001b[39m# was passed to throw().  This prevents a StopIteration\u001b[39;00m\n\u001b[1;32m    141\u001b[0m     \u001b[39m# raised inside the \"with\" statement from being suppressed.\u001b[39;00m\n",
      "File \u001b[0;32m~/anaconda3/envs/llm4/lib/python3.9/site-packages/httpx/_transports/default.py:84\u001b[0m, in \u001b[0;36mmap_httpcore_exceptions\u001b[0;34m()\u001b[0m\n\u001b[1;32m     83\u001b[0m message \u001b[39m=\u001b[39m \u001b[39mstr\u001b[39m(exc)\n\u001b[0;32m---> 84\u001b[0m \u001b[39mraise\u001b[39;00m mapped_exc(message) \u001b[39mfrom\u001b[39;00m \u001b[39mexc\u001b[39;00m\n",
      "\u001b[0;31mConnectError\u001b[0m: [Errno -3] Temporary failure in name resolution",
      "\nDuring handling of the above exception, another exception occurred:\n",
      "\u001b[0;31mgaierror\u001b[0m                                  Traceback (most recent call last)",
      "File \u001b[0;32m~/anaconda3/envs/llm4/lib/python3.9/site-packages/httpcore/_exceptions.py:10\u001b[0m, in \u001b[0;36mmap_exceptions\u001b[0;34m(map)\u001b[0m\n\u001b[1;32m      9\u001b[0m \u001b[39mtry\u001b[39;00m:\n\u001b[0;32m---> 10\u001b[0m     \u001b[39myield\u001b[39;00m\n\u001b[1;32m     11\u001b[0m \u001b[39mexcept\u001b[39;00m \u001b[39mException\u001b[39;00m \u001b[39mas\u001b[39;00m exc:  \u001b[39m# noqa: PIE786\u001b[39;00m\n",
      "File \u001b[0;32m~/anaconda3/envs/llm4/lib/python3.9/site-packages/httpcore/_backends/sync.py:206\u001b[0m, in \u001b[0;36mSyncBackend.connect_tcp\u001b[0;34m(self, host, port, timeout, local_address, socket_options)\u001b[0m\n\u001b[1;32m    205\u001b[0m \u001b[39mwith\u001b[39;00m map_exceptions(exc_map):\n\u001b[0;32m--> 206\u001b[0m     sock \u001b[39m=\u001b[39m socket\u001b[39m.\u001b[39;49mcreate_connection(\n\u001b[1;32m    207\u001b[0m         address,\n\u001b[1;32m    208\u001b[0m         timeout,\n\u001b[1;32m    209\u001b[0m         source_address\u001b[39m=\u001b[39;49msource_address,\n\u001b[1;32m    210\u001b[0m     )\n\u001b[1;32m    211\u001b[0m     \u001b[39mfor\u001b[39;00m option \u001b[39min\u001b[39;00m socket_options:\n",
      "File \u001b[0;32m~/anaconda3/envs/llm4/lib/python3.9/socket.py:823\u001b[0m, in \u001b[0;36mcreate_connection\u001b[0;34m(address, timeout, source_address)\u001b[0m\n\u001b[1;32m    822\u001b[0m err \u001b[39m=\u001b[39m \u001b[39mNone\u001b[39;00m\n\u001b[0;32m--> 823\u001b[0m \u001b[39mfor\u001b[39;00m res \u001b[39min\u001b[39;00m getaddrinfo(host, port, \u001b[39m0\u001b[39;49m, SOCK_STREAM):\n\u001b[1;32m    824\u001b[0m     af, socktype, proto, canonname, sa \u001b[39m=\u001b[39m res\n",
      "File \u001b[0;32m~/anaconda3/envs/llm4/lib/python3.9/socket.py:954\u001b[0m, in \u001b[0;36mgetaddrinfo\u001b[0;34m(host, port, family, type, proto, flags)\u001b[0m\n\u001b[1;32m    953\u001b[0m addrlist \u001b[39m=\u001b[39m []\n\u001b[0;32m--> 954\u001b[0m \u001b[39mfor\u001b[39;00m res \u001b[39min\u001b[39;00m _socket\u001b[39m.\u001b[39;49mgetaddrinfo(host, port, family, \u001b[39mtype\u001b[39;49m, proto, flags):\n\u001b[1;32m    955\u001b[0m     af, socktype, proto, canonname, sa \u001b[39m=\u001b[39m res\n",
      "\u001b[0;31mgaierror\u001b[0m: [Errno -3] Temporary failure in name resolution",
      "\nThe above exception was the direct cause of the following exception:\n",
      "\u001b[0;31mConnectError\u001b[0m                              Traceback (most recent call last)",
      "File \u001b[0;32m~/anaconda3/envs/llm4/lib/python3.9/site-packages/httpx/_transports/default.py:67\u001b[0m, in \u001b[0;36mmap_httpcore_exceptions\u001b[0;34m()\u001b[0m\n\u001b[1;32m     66\u001b[0m \u001b[39mtry\u001b[39;00m:\n\u001b[0;32m---> 67\u001b[0m     \u001b[39myield\u001b[39;00m\n\u001b[1;32m     68\u001b[0m \u001b[39mexcept\u001b[39;00m \u001b[39mException\u001b[39;00m \u001b[39mas\u001b[39;00m exc:\n",
      "File \u001b[0;32m~/anaconda3/envs/llm4/lib/python3.9/site-packages/httpx/_transports/default.py:231\u001b[0m, in \u001b[0;36mHTTPTransport.handle_request\u001b[0;34m(self, request)\u001b[0m\n\u001b[1;32m    230\u001b[0m \u001b[39mwith\u001b[39;00m map_httpcore_exceptions():\n\u001b[0;32m--> 231\u001b[0m     resp \u001b[39m=\u001b[39m \u001b[39mself\u001b[39;49m\u001b[39m.\u001b[39;49m_pool\u001b[39m.\u001b[39;49mhandle_request(req)\n\u001b[1;32m    233\u001b[0m \u001b[39massert\u001b[39;00m \u001b[39misinstance\u001b[39m(resp\u001b[39m.\u001b[39mstream, typing\u001b[39m.\u001b[39mIterable)\n",
      "File \u001b[0;32m~/anaconda3/envs/llm4/lib/python3.9/site-packages/httpcore/_sync/connection_pool.py:268\u001b[0m, in \u001b[0;36mConnectionPool.handle_request\u001b[0;34m(self, request)\u001b[0m\n\u001b[1;32m    267\u001b[0m         \u001b[39mself\u001b[39m\u001b[39m.\u001b[39mresponse_closed(status)\n\u001b[0;32m--> 268\u001b[0m     \u001b[39mraise\u001b[39;00m exc\n\u001b[1;32m    269\u001b[0m \u001b[39melse\u001b[39;00m:\n",
      "File \u001b[0;32m~/anaconda3/envs/llm4/lib/python3.9/site-packages/httpcore/_sync/connection_pool.py:251\u001b[0m, in \u001b[0;36mConnectionPool.handle_request\u001b[0;34m(self, request)\u001b[0m\n\u001b[1;32m    250\u001b[0m \u001b[39mtry\u001b[39;00m:\n\u001b[0;32m--> 251\u001b[0m     response \u001b[39m=\u001b[39m connection\u001b[39m.\u001b[39;49mhandle_request(request)\n\u001b[1;32m    252\u001b[0m \u001b[39mexcept\u001b[39;00m ConnectionNotAvailable:\n\u001b[1;32m    253\u001b[0m     \u001b[39m# The ConnectionNotAvailable exception is a special case, that\u001b[39;00m\n\u001b[1;32m    254\u001b[0m     \u001b[39m# indicates we need to retry the request on a new connection.\u001b[39;00m\n\u001b[0;32m   (...)\u001b[0m\n\u001b[1;32m    258\u001b[0m     \u001b[39m# might end up as an HTTP/2 connection, but which actually ends\u001b[39;00m\n\u001b[1;32m    259\u001b[0m     \u001b[39m# up as HTTP/1.1.\u001b[39;00m\n",
      "File \u001b[0;32m~/anaconda3/envs/llm4/lib/python3.9/site-packages/httpcore/_sync/connection.py:99\u001b[0m, in \u001b[0;36mHTTPConnection.handle_request\u001b[0;34m(self, request)\u001b[0m\n\u001b[1;32m     98\u001b[0m         \u001b[39mself\u001b[39m\u001b[39m.\u001b[39m_connect_failed \u001b[39m=\u001b[39m \u001b[39mTrue\u001b[39;00m\n\u001b[0;32m---> 99\u001b[0m         \u001b[39mraise\u001b[39;00m exc\n\u001b[1;32m    100\u001b[0m \u001b[39melif\u001b[39;00m \u001b[39mnot\u001b[39;00m \u001b[39mself\u001b[39m\u001b[39m.\u001b[39m_connection\u001b[39m.\u001b[39mis_available():\n",
      "File \u001b[0;32m~/anaconda3/envs/llm4/lib/python3.9/site-packages/httpcore/_sync/connection.py:76\u001b[0m, in \u001b[0;36mHTTPConnection.handle_request\u001b[0;34m(self, request)\u001b[0m\n\u001b[1;32m     75\u001b[0m \u001b[39mtry\u001b[39;00m:\n\u001b[0;32m---> 76\u001b[0m     stream \u001b[39m=\u001b[39m \u001b[39mself\u001b[39;49m\u001b[39m.\u001b[39;49m_connect(request)\n\u001b[1;32m     78\u001b[0m     ssl_object \u001b[39m=\u001b[39m stream\u001b[39m.\u001b[39mget_extra_info(\u001b[39m\"\u001b[39m\u001b[39mssl_object\u001b[39m\u001b[39m\"\u001b[39m)\n",
      "File \u001b[0;32m~/anaconda3/envs/llm4/lib/python3.9/site-packages/httpcore/_sync/connection.py:124\u001b[0m, in \u001b[0;36mHTTPConnection._connect\u001b[0;34m(self, request)\u001b[0m\n\u001b[1;32m    123\u001b[0m \u001b[39mwith\u001b[39;00m Trace(\u001b[39m\"\u001b[39m\u001b[39mconnect_tcp\u001b[39m\u001b[39m\"\u001b[39m, logger, request, kwargs) \u001b[39mas\u001b[39;00m trace:\n\u001b[0;32m--> 124\u001b[0m     stream \u001b[39m=\u001b[39m \u001b[39mself\u001b[39;49m\u001b[39m.\u001b[39;49m_network_backend\u001b[39m.\u001b[39;49mconnect_tcp(\u001b[39m*\u001b[39;49m\u001b[39m*\u001b[39;49mkwargs)\n\u001b[1;32m    125\u001b[0m     trace\u001b[39m.\u001b[39mreturn_value \u001b[39m=\u001b[39m stream\n",
      "File \u001b[0;32m~/anaconda3/envs/llm4/lib/python3.9/site-packages/httpcore/_backends/sync.py:213\u001b[0m, in \u001b[0;36mSyncBackend.connect_tcp\u001b[0;34m(self, host, port, timeout, local_address, socket_options)\u001b[0m\n\u001b[1;32m    212\u001b[0m         sock\u001b[39m.\u001b[39msetsockopt(\u001b[39m*\u001b[39moption)  \u001b[39m# pragma: no cover\u001b[39;00m\n\u001b[0;32m--> 213\u001b[0m     sock\u001b[39m.\u001b[39msetsockopt(socket\u001b[39m.\u001b[39mIPPROTO_TCP, socket\u001b[39m.\u001b[39mTCP_NODELAY, \u001b[39m1\u001b[39m)\n\u001b[1;32m    214\u001b[0m \u001b[39mreturn\u001b[39;00m SyncStream(sock)\n",
      "File \u001b[0;32m~/anaconda3/envs/llm4/lib/python3.9/contextlib.py:137\u001b[0m, in \u001b[0;36m_GeneratorContextManager.__exit__\u001b[0;34m(self, typ, value, traceback)\u001b[0m\n\u001b[1;32m    136\u001b[0m \u001b[39mtry\u001b[39;00m:\n\u001b[0;32m--> 137\u001b[0m     \u001b[39mself\u001b[39;49m\u001b[39m.\u001b[39;49mgen\u001b[39m.\u001b[39;49mthrow(typ, value, traceback)\n\u001b[1;32m    138\u001b[0m \u001b[39mexcept\u001b[39;00m \u001b[39mStopIteration\u001b[39;00m \u001b[39mas\u001b[39;00m exc:\n\u001b[1;32m    139\u001b[0m     \u001b[39m# Suppress StopIteration *unless* it's the same exception that\u001b[39;00m\n\u001b[1;32m    140\u001b[0m     \u001b[39m# was passed to throw().  This prevents a StopIteration\u001b[39;00m\n\u001b[1;32m    141\u001b[0m     \u001b[39m# raised inside the \"with\" statement from being suppressed.\u001b[39;00m\n",
      "File \u001b[0;32m~/anaconda3/envs/llm4/lib/python3.9/site-packages/httpcore/_exceptions.py:14\u001b[0m, in \u001b[0;36mmap_exceptions\u001b[0;34m(map)\u001b[0m\n\u001b[1;32m     13\u001b[0m     \u001b[39mif\u001b[39;00m \u001b[39misinstance\u001b[39m(exc, from_exc):\n\u001b[0;32m---> 14\u001b[0m         \u001b[39mraise\u001b[39;00m to_exc(exc) \u001b[39mfrom\u001b[39;00m \u001b[39mexc\u001b[39;00m\n\u001b[1;32m     15\u001b[0m \u001b[39mraise\u001b[39;00m\n",
      "\u001b[0;31mConnectError\u001b[0m: [Errno -3] Temporary failure in name resolution",
      "\nThe above exception was the direct cause of the following exception:\n",
      "\u001b[0;31mConnectError\u001b[0m                              Traceback (most recent call last)",
      "File \u001b[0;32m~/anaconda3/envs/llm4/lib/python3.9/site-packages/openai/_base_client.py:918\u001b[0m, in \u001b[0;36mSyncAPIClient._request\u001b[0;34m(self, cast_to, options, remaining_retries, stream, stream_cls)\u001b[0m\n\u001b[1;32m    917\u001b[0m \u001b[39mtry\u001b[39;00m:\n\u001b[0;32m--> 918\u001b[0m     response \u001b[39m=\u001b[39m \u001b[39mself\u001b[39;49m\u001b[39m.\u001b[39;49m_client\u001b[39m.\u001b[39;49msend(\n\u001b[1;32m    919\u001b[0m         request,\n\u001b[1;32m    920\u001b[0m         stream\u001b[39m=\u001b[39;49mstream \u001b[39mor\u001b[39;49;00m \u001b[39mself\u001b[39;49m\u001b[39m.\u001b[39;49m_should_stream_response_body(request\u001b[39m=\u001b[39;49mrequest),\n\u001b[1;32m    921\u001b[0m         \u001b[39m*\u001b[39;49m\u001b[39m*\u001b[39;49mkwargs,\n\u001b[1;32m    922\u001b[0m     )\n\u001b[1;32m    923\u001b[0m \u001b[39mexcept\u001b[39;00m httpx\u001b[39m.\u001b[39mTimeoutException \u001b[39mas\u001b[39;00m err:\n",
      "File \u001b[0;32m~/anaconda3/envs/llm4/lib/python3.9/site-packages/httpx/_client.py:915\u001b[0m, in \u001b[0;36mClient.send\u001b[0;34m(self, request, stream, auth, follow_redirects)\u001b[0m\n\u001b[1;32m    913\u001b[0m auth \u001b[39m=\u001b[39m \u001b[39mself\u001b[39m\u001b[39m.\u001b[39m_build_request_auth(request, auth)\n\u001b[0;32m--> 915\u001b[0m response \u001b[39m=\u001b[39m \u001b[39mself\u001b[39;49m\u001b[39m.\u001b[39;49m_send_handling_auth(\n\u001b[1;32m    916\u001b[0m     request,\n\u001b[1;32m    917\u001b[0m     auth\u001b[39m=\u001b[39;49mauth,\n\u001b[1;32m    918\u001b[0m     follow_redirects\u001b[39m=\u001b[39;49mfollow_redirects,\n\u001b[1;32m    919\u001b[0m     history\u001b[39m=\u001b[39;49m[],\n\u001b[1;32m    920\u001b[0m )\n\u001b[1;32m    921\u001b[0m \u001b[39mtry\u001b[39;00m:\n",
      "File \u001b[0;32m~/anaconda3/envs/llm4/lib/python3.9/site-packages/httpx/_client.py:943\u001b[0m, in \u001b[0;36mClient._send_handling_auth\u001b[0;34m(self, request, auth, follow_redirects, history)\u001b[0m\n\u001b[1;32m    942\u001b[0m \u001b[39mwhile\u001b[39;00m \u001b[39mTrue\u001b[39;00m:\n\u001b[0;32m--> 943\u001b[0m     response \u001b[39m=\u001b[39m \u001b[39mself\u001b[39;49m\u001b[39m.\u001b[39;49m_send_handling_redirects(\n\u001b[1;32m    944\u001b[0m         request,\n\u001b[1;32m    945\u001b[0m         follow_redirects\u001b[39m=\u001b[39;49mfollow_redirects,\n\u001b[1;32m    946\u001b[0m         history\u001b[39m=\u001b[39;49mhistory,\n\u001b[1;32m    947\u001b[0m     )\n\u001b[1;32m    948\u001b[0m     \u001b[39mtry\u001b[39;00m:\n",
      "File \u001b[0;32m~/anaconda3/envs/llm4/lib/python3.9/site-packages/httpx/_client.py:980\u001b[0m, in \u001b[0;36mClient._send_handling_redirects\u001b[0;34m(self, request, follow_redirects, history)\u001b[0m\n\u001b[1;32m    978\u001b[0m     hook(request)\n\u001b[0;32m--> 980\u001b[0m response \u001b[39m=\u001b[39m \u001b[39mself\u001b[39;49m\u001b[39m.\u001b[39;49m_send_single_request(request)\n\u001b[1;32m    981\u001b[0m \u001b[39mtry\u001b[39;00m:\n",
      "File \u001b[0;32m~/anaconda3/envs/llm4/lib/python3.9/site-packages/httpx/_client.py:1016\u001b[0m, in \u001b[0;36mClient._send_single_request\u001b[0;34m(self, request)\u001b[0m\n\u001b[1;32m   1015\u001b[0m \u001b[39mwith\u001b[39;00m request_context(request\u001b[39m=\u001b[39mrequest):\n\u001b[0;32m-> 1016\u001b[0m     response \u001b[39m=\u001b[39m transport\u001b[39m.\u001b[39;49mhandle_request(request)\n\u001b[1;32m   1018\u001b[0m \u001b[39massert\u001b[39;00m \u001b[39misinstance\u001b[39m(response\u001b[39m.\u001b[39mstream, SyncByteStream)\n",
      "File \u001b[0;32m~/anaconda3/envs/llm4/lib/python3.9/site-packages/httpx/_transports/default.py:231\u001b[0m, in \u001b[0;36mHTTPTransport.handle_request\u001b[0;34m(self, request)\u001b[0m\n\u001b[1;32m    230\u001b[0m \u001b[39mwith\u001b[39;00m map_httpcore_exceptions():\n\u001b[0;32m--> 231\u001b[0m     resp \u001b[39m=\u001b[39m \u001b[39mself\u001b[39m\u001b[39m.\u001b[39m_pool\u001b[39m.\u001b[39mhandle_request(req)\n\u001b[1;32m    233\u001b[0m \u001b[39massert\u001b[39;00m \u001b[39misinstance\u001b[39m(resp\u001b[39m.\u001b[39mstream, typing\u001b[39m.\u001b[39mIterable)\n",
      "File \u001b[0;32m~/anaconda3/envs/llm4/lib/python3.9/contextlib.py:137\u001b[0m, in \u001b[0;36m_GeneratorContextManager.__exit__\u001b[0;34m(self, typ, value, traceback)\u001b[0m\n\u001b[1;32m    136\u001b[0m \u001b[39mtry\u001b[39;00m:\n\u001b[0;32m--> 137\u001b[0m     \u001b[39mself\u001b[39;49m\u001b[39m.\u001b[39;49mgen\u001b[39m.\u001b[39;49mthrow(typ, value, traceback)\n\u001b[1;32m    138\u001b[0m \u001b[39mexcept\u001b[39;00m \u001b[39mStopIteration\u001b[39;00m \u001b[39mas\u001b[39;00m exc:\n\u001b[1;32m    139\u001b[0m     \u001b[39m# Suppress StopIteration *unless* it's the same exception that\u001b[39;00m\n\u001b[1;32m    140\u001b[0m     \u001b[39m# was passed to throw().  This prevents a StopIteration\u001b[39;00m\n\u001b[1;32m    141\u001b[0m     \u001b[39m# raised inside the \"with\" statement from being suppressed.\u001b[39;00m\n",
      "File \u001b[0;32m~/anaconda3/envs/llm4/lib/python3.9/site-packages/httpx/_transports/default.py:84\u001b[0m, in \u001b[0;36mmap_httpcore_exceptions\u001b[0;34m()\u001b[0m\n\u001b[1;32m     83\u001b[0m message \u001b[39m=\u001b[39m \u001b[39mstr\u001b[39m(exc)\n\u001b[0;32m---> 84\u001b[0m \u001b[39mraise\u001b[39;00m mapped_exc(message) \u001b[39mfrom\u001b[39;00m \u001b[39mexc\u001b[39;00m\n",
      "\u001b[0;31mConnectError\u001b[0m: [Errno -3] Temporary failure in name resolution",
      "\nDuring handling of the above exception, another exception occurred:\n",
      "\u001b[0;31mgaierror\u001b[0m                                  Traceback (most recent call last)",
      "File \u001b[0;32m~/anaconda3/envs/llm4/lib/python3.9/site-packages/httpcore/_exceptions.py:10\u001b[0m, in \u001b[0;36mmap_exceptions\u001b[0;34m(map)\u001b[0m\n\u001b[1;32m      9\u001b[0m \u001b[39mtry\u001b[39;00m:\n\u001b[0;32m---> 10\u001b[0m     \u001b[39myield\u001b[39;00m\n\u001b[1;32m     11\u001b[0m \u001b[39mexcept\u001b[39;00m \u001b[39mException\u001b[39;00m \u001b[39mas\u001b[39;00m exc:  \u001b[39m# noqa: PIE786\u001b[39;00m\n",
      "File \u001b[0;32m~/anaconda3/envs/llm4/lib/python3.9/site-packages/httpcore/_backends/sync.py:206\u001b[0m, in \u001b[0;36mSyncBackend.connect_tcp\u001b[0;34m(self, host, port, timeout, local_address, socket_options)\u001b[0m\n\u001b[1;32m    205\u001b[0m \u001b[39mwith\u001b[39;00m map_exceptions(exc_map):\n\u001b[0;32m--> 206\u001b[0m     sock \u001b[39m=\u001b[39m socket\u001b[39m.\u001b[39;49mcreate_connection(\n\u001b[1;32m    207\u001b[0m         address,\n\u001b[1;32m    208\u001b[0m         timeout,\n\u001b[1;32m    209\u001b[0m         source_address\u001b[39m=\u001b[39;49msource_address,\n\u001b[1;32m    210\u001b[0m     )\n\u001b[1;32m    211\u001b[0m     \u001b[39mfor\u001b[39;00m option \u001b[39min\u001b[39;00m socket_options:\n",
      "File \u001b[0;32m~/anaconda3/envs/llm4/lib/python3.9/socket.py:823\u001b[0m, in \u001b[0;36mcreate_connection\u001b[0;34m(address, timeout, source_address)\u001b[0m\n\u001b[1;32m    822\u001b[0m err \u001b[39m=\u001b[39m \u001b[39mNone\u001b[39;00m\n\u001b[0;32m--> 823\u001b[0m \u001b[39mfor\u001b[39;00m res \u001b[39min\u001b[39;00m getaddrinfo(host, port, \u001b[39m0\u001b[39;49m, SOCK_STREAM):\n\u001b[1;32m    824\u001b[0m     af, socktype, proto, canonname, sa \u001b[39m=\u001b[39m res\n",
      "File \u001b[0;32m~/anaconda3/envs/llm4/lib/python3.9/socket.py:954\u001b[0m, in \u001b[0;36mgetaddrinfo\u001b[0;34m(host, port, family, type, proto, flags)\u001b[0m\n\u001b[1;32m    953\u001b[0m addrlist \u001b[39m=\u001b[39m []\n\u001b[0;32m--> 954\u001b[0m \u001b[39mfor\u001b[39;00m res \u001b[39min\u001b[39;00m _socket\u001b[39m.\u001b[39;49mgetaddrinfo(host, port, family, \u001b[39mtype\u001b[39;49m, proto, flags):\n\u001b[1;32m    955\u001b[0m     af, socktype, proto, canonname, sa \u001b[39m=\u001b[39m res\n",
      "\u001b[0;31mgaierror\u001b[0m: [Errno -3] Temporary failure in name resolution",
      "\nThe above exception was the direct cause of the following exception:\n",
      "\u001b[0;31mConnectError\u001b[0m                              Traceback (most recent call last)",
      "File \u001b[0;32m~/anaconda3/envs/llm4/lib/python3.9/site-packages/httpx/_transports/default.py:67\u001b[0m, in \u001b[0;36mmap_httpcore_exceptions\u001b[0;34m()\u001b[0m\n\u001b[1;32m     66\u001b[0m \u001b[39mtry\u001b[39;00m:\n\u001b[0;32m---> 67\u001b[0m     \u001b[39myield\u001b[39;00m\n\u001b[1;32m     68\u001b[0m \u001b[39mexcept\u001b[39;00m \u001b[39mException\u001b[39;00m \u001b[39mas\u001b[39;00m exc:\n",
      "File \u001b[0;32m~/anaconda3/envs/llm4/lib/python3.9/site-packages/httpx/_transports/default.py:231\u001b[0m, in \u001b[0;36mHTTPTransport.handle_request\u001b[0;34m(self, request)\u001b[0m\n\u001b[1;32m    230\u001b[0m \u001b[39mwith\u001b[39;00m map_httpcore_exceptions():\n\u001b[0;32m--> 231\u001b[0m     resp \u001b[39m=\u001b[39m \u001b[39mself\u001b[39;49m\u001b[39m.\u001b[39;49m_pool\u001b[39m.\u001b[39;49mhandle_request(req)\n\u001b[1;32m    233\u001b[0m \u001b[39massert\u001b[39;00m \u001b[39misinstance\u001b[39m(resp\u001b[39m.\u001b[39mstream, typing\u001b[39m.\u001b[39mIterable)\n",
      "File \u001b[0;32m~/anaconda3/envs/llm4/lib/python3.9/site-packages/httpcore/_sync/connection_pool.py:268\u001b[0m, in \u001b[0;36mConnectionPool.handle_request\u001b[0;34m(self, request)\u001b[0m\n\u001b[1;32m    267\u001b[0m         \u001b[39mself\u001b[39m\u001b[39m.\u001b[39mresponse_closed(status)\n\u001b[0;32m--> 268\u001b[0m     \u001b[39mraise\u001b[39;00m exc\n\u001b[1;32m    269\u001b[0m \u001b[39melse\u001b[39;00m:\n",
      "File \u001b[0;32m~/anaconda3/envs/llm4/lib/python3.9/site-packages/httpcore/_sync/connection_pool.py:251\u001b[0m, in \u001b[0;36mConnectionPool.handle_request\u001b[0;34m(self, request)\u001b[0m\n\u001b[1;32m    250\u001b[0m \u001b[39mtry\u001b[39;00m:\n\u001b[0;32m--> 251\u001b[0m     response \u001b[39m=\u001b[39m connection\u001b[39m.\u001b[39;49mhandle_request(request)\n\u001b[1;32m    252\u001b[0m \u001b[39mexcept\u001b[39;00m ConnectionNotAvailable:\n\u001b[1;32m    253\u001b[0m     \u001b[39m# The ConnectionNotAvailable exception is a special case, that\u001b[39;00m\n\u001b[1;32m    254\u001b[0m     \u001b[39m# indicates we need to retry the request on a new connection.\u001b[39;00m\n\u001b[0;32m   (...)\u001b[0m\n\u001b[1;32m    258\u001b[0m     \u001b[39m# might end up as an HTTP/2 connection, but which actually ends\u001b[39;00m\n\u001b[1;32m    259\u001b[0m     \u001b[39m# up as HTTP/1.1.\u001b[39;00m\n",
      "File \u001b[0;32m~/anaconda3/envs/llm4/lib/python3.9/site-packages/httpcore/_sync/connection.py:99\u001b[0m, in \u001b[0;36mHTTPConnection.handle_request\u001b[0;34m(self, request)\u001b[0m\n\u001b[1;32m     98\u001b[0m         \u001b[39mself\u001b[39m\u001b[39m.\u001b[39m_connect_failed \u001b[39m=\u001b[39m \u001b[39mTrue\u001b[39;00m\n\u001b[0;32m---> 99\u001b[0m         \u001b[39mraise\u001b[39;00m exc\n\u001b[1;32m    100\u001b[0m \u001b[39melif\u001b[39;00m \u001b[39mnot\u001b[39;00m \u001b[39mself\u001b[39m\u001b[39m.\u001b[39m_connection\u001b[39m.\u001b[39mis_available():\n",
      "File \u001b[0;32m~/anaconda3/envs/llm4/lib/python3.9/site-packages/httpcore/_sync/connection.py:76\u001b[0m, in \u001b[0;36mHTTPConnection.handle_request\u001b[0;34m(self, request)\u001b[0m\n\u001b[1;32m     75\u001b[0m \u001b[39mtry\u001b[39;00m:\n\u001b[0;32m---> 76\u001b[0m     stream \u001b[39m=\u001b[39m \u001b[39mself\u001b[39;49m\u001b[39m.\u001b[39;49m_connect(request)\n\u001b[1;32m     78\u001b[0m     ssl_object \u001b[39m=\u001b[39m stream\u001b[39m.\u001b[39mget_extra_info(\u001b[39m\"\u001b[39m\u001b[39mssl_object\u001b[39m\u001b[39m\"\u001b[39m)\n",
      "File \u001b[0;32m~/anaconda3/envs/llm4/lib/python3.9/site-packages/httpcore/_sync/connection.py:124\u001b[0m, in \u001b[0;36mHTTPConnection._connect\u001b[0;34m(self, request)\u001b[0m\n\u001b[1;32m    123\u001b[0m \u001b[39mwith\u001b[39;00m Trace(\u001b[39m\"\u001b[39m\u001b[39mconnect_tcp\u001b[39m\u001b[39m\"\u001b[39m, logger, request, kwargs) \u001b[39mas\u001b[39;00m trace:\n\u001b[0;32m--> 124\u001b[0m     stream \u001b[39m=\u001b[39m \u001b[39mself\u001b[39;49m\u001b[39m.\u001b[39;49m_network_backend\u001b[39m.\u001b[39;49mconnect_tcp(\u001b[39m*\u001b[39;49m\u001b[39m*\u001b[39;49mkwargs)\n\u001b[1;32m    125\u001b[0m     trace\u001b[39m.\u001b[39mreturn_value \u001b[39m=\u001b[39m stream\n",
      "File \u001b[0;32m~/anaconda3/envs/llm4/lib/python3.9/site-packages/httpcore/_backends/sync.py:213\u001b[0m, in \u001b[0;36mSyncBackend.connect_tcp\u001b[0;34m(self, host, port, timeout, local_address, socket_options)\u001b[0m\n\u001b[1;32m    212\u001b[0m         sock\u001b[39m.\u001b[39msetsockopt(\u001b[39m*\u001b[39moption)  \u001b[39m# pragma: no cover\u001b[39;00m\n\u001b[0;32m--> 213\u001b[0m     sock\u001b[39m.\u001b[39msetsockopt(socket\u001b[39m.\u001b[39mIPPROTO_TCP, socket\u001b[39m.\u001b[39mTCP_NODELAY, \u001b[39m1\u001b[39m)\n\u001b[1;32m    214\u001b[0m \u001b[39mreturn\u001b[39;00m SyncStream(sock)\n",
      "File \u001b[0;32m~/anaconda3/envs/llm4/lib/python3.9/contextlib.py:137\u001b[0m, in \u001b[0;36m_GeneratorContextManager.__exit__\u001b[0;34m(self, typ, value, traceback)\u001b[0m\n\u001b[1;32m    136\u001b[0m \u001b[39mtry\u001b[39;00m:\n\u001b[0;32m--> 137\u001b[0m     \u001b[39mself\u001b[39;49m\u001b[39m.\u001b[39;49mgen\u001b[39m.\u001b[39;49mthrow(typ, value, traceback)\n\u001b[1;32m    138\u001b[0m \u001b[39mexcept\u001b[39;00m \u001b[39mStopIteration\u001b[39;00m \u001b[39mas\u001b[39;00m exc:\n\u001b[1;32m    139\u001b[0m     \u001b[39m# Suppress StopIteration *unless* it's the same exception that\u001b[39;00m\n\u001b[1;32m    140\u001b[0m     \u001b[39m# was passed to throw().  This prevents a StopIteration\u001b[39;00m\n\u001b[1;32m    141\u001b[0m     \u001b[39m# raised inside the \"with\" statement from being suppressed.\u001b[39;00m\n",
      "File \u001b[0;32m~/anaconda3/envs/llm4/lib/python3.9/site-packages/httpcore/_exceptions.py:14\u001b[0m, in \u001b[0;36mmap_exceptions\u001b[0;34m(map)\u001b[0m\n\u001b[1;32m     13\u001b[0m     \u001b[39mif\u001b[39;00m \u001b[39misinstance\u001b[39m(exc, from_exc):\n\u001b[0;32m---> 14\u001b[0m         \u001b[39mraise\u001b[39;00m to_exc(exc) \u001b[39mfrom\u001b[39;00m \u001b[39mexc\u001b[39;00m\n\u001b[1;32m     15\u001b[0m \u001b[39mraise\u001b[39;00m\n",
      "\u001b[0;31mConnectError\u001b[0m: [Errno -3] Temporary failure in name resolution",
      "\nThe above exception was the direct cause of the following exception:\n",
      "\u001b[0;31mConnectError\u001b[0m                              Traceback (most recent call last)",
      "File \u001b[0;32m~/anaconda3/envs/llm4/lib/python3.9/site-packages/openai/_base_client.py:918\u001b[0m, in \u001b[0;36mSyncAPIClient._request\u001b[0;34m(self, cast_to, options, remaining_retries, stream, stream_cls)\u001b[0m\n\u001b[1;32m    917\u001b[0m \u001b[39mtry\u001b[39;00m:\n\u001b[0;32m--> 918\u001b[0m     response \u001b[39m=\u001b[39m \u001b[39mself\u001b[39;49m\u001b[39m.\u001b[39;49m_client\u001b[39m.\u001b[39;49msend(\n\u001b[1;32m    919\u001b[0m         request,\n\u001b[1;32m    920\u001b[0m         stream\u001b[39m=\u001b[39;49mstream \u001b[39mor\u001b[39;49;00m \u001b[39mself\u001b[39;49m\u001b[39m.\u001b[39;49m_should_stream_response_body(request\u001b[39m=\u001b[39;49mrequest),\n\u001b[1;32m    921\u001b[0m         \u001b[39m*\u001b[39;49m\u001b[39m*\u001b[39;49mkwargs,\n\u001b[1;32m    922\u001b[0m     )\n\u001b[1;32m    923\u001b[0m \u001b[39mexcept\u001b[39;00m httpx\u001b[39m.\u001b[39mTimeoutException \u001b[39mas\u001b[39;00m err:\n",
      "File \u001b[0;32m~/anaconda3/envs/llm4/lib/python3.9/site-packages/httpx/_client.py:915\u001b[0m, in \u001b[0;36mClient.send\u001b[0;34m(self, request, stream, auth, follow_redirects)\u001b[0m\n\u001b[1;32m    913\u001b[0m auth \u001b[39m=\u001b[39m \u001b[39mself\u001b[39m\u001b[39m.\u001b[39m_build_request_auth(request, auth)\n\u001b[0;32m--> 915\u001b[0m response \u001b[39m=\u001b[39m \u001b[39mself\u001b[39;49m\u001b[39m.\u001b[39;49m_send_handling_auth(\n\u001b[1;32m    916\u001b[0m     request,\n\u001b[1;32m    917\u001b[0m     auth\u001b[39m=\u001b[39;49mauth,\n\u001b[1;32m    918\u001b[0m     follow_redirects\u001b[39m=\u001b[39;49mfollow_redirects,\n\u001b[1;32m    919\u001b[0m     history\u001b[39m=\u001b[39;49m[],\n\u001b[1;32m    920\u001b[0m )\n\u001b[1;32m    921\u001b[0m \u001b[39mtry\u001b[39;00m:\n",
      "File \u001b[0;32m~/anaconda3/envs/llm4/lib/python3.9/site-packages/httpx/_client.py:943\u001b[0m, in \u001b[0;36mClient._send_handling_auth\u001b[0;34m(self, request, auth, follow_redirects, history)\u001b[0m\n\u001b[1;32m    942\u001b[0m \u001b[39mwhile\u001b[39;00m \u001b[39mTrue\u001b[39;00m:\n\u001b[0;32m--> 943\u001b[0m     response \u001b[39m=\u001b[39m \u001b[39mself\u001b[39;49m\u001b[39m.\u001b[39;49m_send_handling_redirects(\n\u001b[1;32m    944\u001b[0m         request,\n\u001b[1;32m    945\u001b[0m         follow_redirects\u001b[39m=\u001b[39;49mfollow_redirects,\n\u001b[1;32m    946\u001b[0m         history\u001b[39m=\u001b[39;49mhistory,\n\u001b[1;32m    947\u001b[0m     )\n\u001b[1;32m    948\u001b[0m     \u001b[39mtry\u001b[39;00m:\n",
      "File \u001b[0;32m~/anaconda3/envs/llm4/lib/python3.9/site-packages/httpx/_client.py:980\u001b[0m, in \u001b[0;36mClient._send_handling_redirects\u001b[0;34m(self, request, follow_redirects, history)\u001b[0m\n\u001b[1;32m    978\u001b[0m     hook(request)\n\u001b[0;32m--> 980\u001b[0m response \u001b[39m=\u001b[39m \u001b[39mself\u001b[39;49m\u001b[39m.\u001b[39;49m_send_single_request(request)\n\u001b[1;32m    981\u001b[0m \u001b[39mtry\u001b[39;00m:\n",
      "File \u001b[0;32m~/anaconda3/envs/llm4/lib/python3.9/site-packages/httpx/_client.py:1016\u001b[0m, in \u001b[0;36mClient._send_single_request\u001b[0;34m(self, request)\u001b[0m\n\u001b[1;32m   1015\u001b[0m \u001b[39mwith\u001b[39;00m request_context(request\u001b[39m=\u001b[39mrequest):\n\u001b[0;32m-> 1016\u001b[0m     response \u001b[39m=\u001b[39m transport\u001b[39m.\u001b[39;49mhandle_request(request)\n\u001b[1;32m   1018\u001b[0m \u001b[39massert\u001b[39;00m \u001b[39misinstance\u001b[39m(response\u001b[39m.\u001b[39mstream, SyncByteStream)\n",
      "File \u001b[0;32m~/anaconda3/envs/llm4/lib/python3.9/site-packages/httpx/_transports/default.py:231\u001b[0m, in \u001b[0;36mHTTPTransport.handle_request\u001b[0;34m(self, request)\u001b[0m\n\u001b[1;32m    230\u001b[0m \u001b[39mwith\u001b[39;00m map_httpcore_exceptions():\n\u001b[0;32m--> 231\u001b[0m     resp \u001b[39m=\u001b[39m \u001b[39mself\u001b[39m\u001b[39m.\u001b[39m_pool\u001b[39m.\u001b[39mhandle_request(req)\n\u001b[1;32m    233\u001b[0m \u001b[39massert\u001b[39;00m \u001b[39misinstance\u001b[39m(resp\u001b[39m.\u001b[39mstream, typing\u001b[39m.\u001b[39mIterable)\n",
      "File \u001b[0;32m~/anaconda3/envs/llm4/lib/python3.9/contextlib.py:137\u001b[0m, in \u001b[0;36m_GeneratorContextManager.__exit__\u001b[0;34m(self, typ, value, traceback)\u001b[0m\n\u001b[1;32m    136\u001b[0m \u001b[39mtry\u001b[39;00m:\n\u001b[0;32m--> 137\u001b[0m     \u001b[39mself\u001b[39;49m\u001b[39m.\u001b[39;49mgen\u001b[39m.\u001b[39;49mthrow(typ, value, traceback)\n\u001b[1;32m    138\u001b[0m \u001b[39mexcept\u001b[39;00m \u001b[39mStopIteration\u001b[39;00m \u001b[39mas\u001b[39;00m exc:\n\u001b[1;32m    139\u001b[0m     \u001b[39m# Suppress StopIteration *unless* it's the same exception that\u001b[39;00m\n\u001b[1;32m    140\u001b[0m     \u001b[39m# was passed to throw().  This prevents a StopIteration\u001b[39;00m\n\u001b[1;32m    141\u001b[0m     \u001b[39m# raised inside the \"with\" statement from being suppressed.\u001b[39;00m\n",
      "File \u001b[0;32m~/anaconda3/envs/llm4/lib/python3.9/site-packages/httpx/_transports/default.py:84\u001b[0m, in \u001b[0;36mmap_httpcore_exceptions\u001b[0;34m()\u001b[0m\n\u001b[1;32m     83\u001b[0m message \u001b[39m=\u001b[39m \u001b[39mstr\u001b[39m(exc)\n\u001b[0;32m---> 84\u001b[0m \u001b[39mraise\u001b[39;00m mapped_exc(message) \u001b[39mfrom\u001b[39;00m \u001b[39mexc\u001b[39;00m\n",
      "\u001b[0;31mConnectError\u001b[0m: [Errno -3] Temporary failure in name resolution",
      "\nThe above exception was the direct cause of the following exception:\n",
      "\u001b[0;31mAPIConnectionError\u001b[0m                        Traceback (most recent call last)",
      "Cell \u001b[0;32mIn[15], line 1\u001b[0m\n\u001b[0;32m----> 1\u001b[0m ai_message \u001b[38;5;241m=\u001b[39m \u001b[43mchat\u001b[49m\u001b[43m(\u001b[49m\u001b[43mmessages\u001b[49m\u001b[43m)\u001b[49m\n",
      "File \u001b[0;32m~/anaconda3/envs/llm4/lib/python3.9/site-packages/langchain_core/_api/deprecation.py:145\u001b[0m, in \u001b[0;36mdeprecated.<locals>.deprecate.<locals>.warning_emitting_wrapper\u001b[0;34m(*args, **kwargs)\u001b[0m\n\u001b[1;32m    143\u001b[0m     warned \u001b[39m=\u001b[39m \u001b[39mTrue\u001b[39;00m\n\u001b[1;32m    144\u001b[0m     emit_warning()\n\u001b[0;32m--> 145\u001b[0m \u001b[39mreturn\u001b[39;00m wrapped(\u001b[39m*\u001b[39;49margs, \u001b[39m*\u001b[39;49m\u001b[39m*\u001b[39;49mkwargs)\n",
      "File \u001b[0;32m~/anaconda3/envs/llm4/lib/python3.9/site-packages/langchain_core/language_models/chat_models.py:691\u001b[0m, in \u001b[0;36mBaseChatModel.__call__\u001b[0;34m(self, messages, stop, callbacks, **kwargs)\u001b[0m\n\u001b[1;32m    683\u001b[0m \u001b[39m@deprecated\u001b[39m(\u001b[39m\"\u001b[39m\u001b[39m0.1.7\u001b[39m\u001b[39m\"\u001b[39m, alternative\u001b[39m=\u001b[39m\u001b[39m\"\u001b[39m\u001b[39minvoke\u001b[39m\u001b[39m\"\u001b[39m, removal\u001b[39m=\u001b[39m\u001b[39m\"\u001b[39m\u001b[39m0.2.0\u001b[39m\u001b[39m\"\u001b[39m)\n\u001b[1;32m    684\u001b[0m \u001b[39mdef\u001b[39;00m \u001b[39m__call__\u001b[39m(\n\u001b[1;32m    685\u001b[0m     \u001b[39mself\u001b[39m,\n\u001b[0;32m   (...)\u001b[0m\n\u001b[1;32m    689\u001b[0m     \u001b[39m*\u001b[39m\u001b[39m*\u001b[39mkwargs: Any,\n\u001b[1;32m    690\u001b[0m ) \u001b[39m-\u001b[39m\u001b[39m>\u001b[39m BaseMessage:\n\u001b[0;32m--> 691\u001b[0m     generation \u001b[39m=\u001b[39m \u001b[39mself\u001b[39;49m\u001b[39m.\u001b[39;49mgenerate(\n\u001b[1;32m    692\u001b[0m         [messages], stop\u001b[39m=\u001b[39;49mstop, callbacks\u001b[39m=\u001b[39;49mcallbacks, \u001b[39m*\u001b[39;49m\u001b[39m*\u001b[39;49mkwargs\n\u001b[1;32m    693\u001b[0m     )\u001b[39m.\u001b[39mgenerations[\u001b[39m0\u001b[39m][\u001b[39m0\u001b[39m]\n\u001b[1;32m    694\u001b[0m     \u001b[39mif\u001b[39;00m \u001b[39misinstance\u001b[39m(generation, ChatGeneration):\n\u001b[1;32m    695\u001b[0m         \u001b[39mreturn\u001b[39;00m generation\u001b[39m.\u001b[39mmessage\n",
      "File \u001b[0;32m~/anaconda3/envs/llm4/lib/python3.9/site-packages/langchain_core/language_models/chat_models.py:408\u001b[0m, in \u001b[0;36mBaseChatModel.generate\u001b[0;34m(self, messages, stop, callbacks, tags, metadata, run_name, **kwargs)\u001b[0m\n\u001b[1;32m    406\u001b[0m         \u001b[39mif\u001b[39;00m run_managers:\n\u001b[1;32m    407\u001b[0m             run_managers[i]\u001b[39m.\u001b[39mon_llm_error(e, response\u001b[39m=\u001b[39mLLMResult(generations\u001b[39m=\u001b[39m[]))\n\u001b[0;32m--> 408\u001b[0m         \u001b[39mraise\u001b[39;00m e\n\u001b[1;32m    409\u001b[0m flattened_outputs \u001b[39m=\u001b[39m [\n\u001b[1;32m    410\u001b[0m     LLMResult(generations\u001b[39m=\u001b[39m[res\u001b[39m.\u001b[39mgenerations], llm_output\u001b[39m=\u001b[39mres\u001b[39m.\u001b[39mllm_output)\n\u001b[1;32m    411\u001b[0m     \u001b[39mfor\u001b[39;00m res \u001b[39min\u001b[39;00m results\n\u001b[1;32m    412\u001b[0m ]\n\u001b[1;32m    413\u001b[0m llm_output \u001b[39m=\u001b[39m \u001b[39mself\u001b[39m\u001b[39m.\u001b[39m_combine_llm_outputs([res\u001b[39m.\u001b[39mllm_output \u001b[39mfor\u001b[39;00m res \u001b[39min\u001b[39;00m results])\n",
      "File \u001b[0;32m~/anaconda3/envs/llm4/lib/python3.9/site-packages/langchain_core/language_models/chat_models.py:398\u001b[0m, in \u001b[0;36mBaseChatModel.generate\u001b[0;34m(self, messages, stop, callbacks, tags, metadata, run_name, **kwargs)\u001b[0m\n\u001b[1;32m    395\u001b[0m \u001b[39mfor\u001b[39;00m i, m \u001b[39min\u001b[39;00m \u001b[39menumerate\u001b[39m(messages):\n\u001b[1;32m    396\u001b[0m     \u001b[39mtry\u001b[39;00m:\n\u001b[1;32m    397\u001b[0m         results\u001b[39m.\u001b[39mappend(\n\u001b[0;32m--> 398\u001b[0m             \u001b[39mself\u001b[39;49m\u001b[39m.\u001b[39;49m_generate_with_cache(\n\u001b[1;32m    399\u001b[0m                 m,\n\u001b[1;32m    400\u001b[0m                 stop\u001b[39m=\u001b[39;49mstop,\n\u001b[1;32m    401\u001b[0m                 run_manager\u001b[39m=\u001b[39;49mrun_managers[i] \u001b[39mif\u001b[39;49;00m run_managers \u001b[39melse\u001b[39;49;00m \u001b[39mNone\u001b[39;49;00m,\n\u001b[1;32m    402\u001b[0m                 \u001b[39m*\u001b[39;49m\u001b[39m*\u001b[39;49mkwargs,\n\u001b[1;32m    403\u001b[0m             )\n\u001b[1;32m    404\u001b[0m         )\n\u001b[1;32m    405\u001b[0m     \u001b[39mexcept\u001b[39;00m \u001b[39mBaseException\u001b[39;00m \u001b[39mas\u001b[39;00m e:\n\u001b[1;32m    406\u001b[0m         \u001b[39mif\u001b[39;00m run_managers:\n",
      "File \u001b[0;32m~/anaconda3/envs/llm4/lib/python3.9/site-packages/langchain_core/language_models/chat_models.py:577\u001b[0m, in \u001b[0;36mBaseChatModel._generate_with_cache\u001b[0;34m(self, messages, stop, run_manager, **kwargs)\u001b[0m\n\u001b[1;32m    573\u001b[0m     \u001b[39mraise\u001b[39;00m \u001b[39mValueError\u001b[39;00m(\n\u001b[1;32m    574\u001b[0m         \u001b[39m\"\u001b[39m\u001b[39mAsked to cache, but no cache found at `langchain.cache`.\u001b[39m\u001b[39m\"\u001b[39m\n\u001b[1;32m    575\u001b[0m     )\n\u001b[1;32m    576\u001b[0m \u001b[39mif\u001b[39;00m new_arg_supported:\n\u001b[0;32m--> 577\u001b[0m     \u001b[39mreturn\u001b[39;00m \u001b[39mself\u001b[39;49m\u001b[39m.\u001b[39;49m_generate(\n\u001b[1;32m    578\u001b[0m         messages, stop\u001b[39m=\u001b[39;49mstop, run_manager\u001b[39m=\u001b[39;49mrun_manager, \u001b[39m*\u001b[39;49m\u001b[39m*\u001b[39;49mkwargs\n\u001b[1;32m    579\u001b[0m     )\n\u001b[1;32m    580\u001b[0m \u001b[39melse\u001b[39;00m:\n\u001b[1;32m    581\u001b[0m     \u001b[39mreturn\u001b[39;00m \u001b[39mself\u001b[39m\u001b[39m.\u001b[39m_generate(messages, stop\u001b[39m=\u001b[39mstop, \u001b[39m*\u001b[39m\u001b[39m*\u001b[39mkwargs)\n",
      "File \u001b[0;32m~/anaconda3/envs/llm4/lib/python3.9/site-packages/langchain_community/chat_models/openai.py:439\u001b[0m, in \u001b[0;36mChatOpenAI._generate\u001b[0;34m(self, messages, stop, run_manager, stream, **kwargs)\u001b[0m\n\u001b[1;32m    433\u001b[0m message_dicts, params \u001b[39m=\u001b[39m \u001b[39mself\u001b[39m\u001b[39m.\u001b[39m_create_message_dicts(messages, stop)\n\u001b[1;32m    434\u001b[0m params \u001b[39m=\u001b[39m {\n\u001b[1;32m    435\u001b[0m     \u001b[39m*\u001b[39m\u001b[39m*\u001b[39mparams,\n\u001b[1;32m    436\u001b[0m     \u001b[39m*\u001b[39m\u001b[39m*\u001b[39m({\u001b[39m\"\u001b[39m\u001b[39mstream\u001b[39m\u001b[39m\"\u001b[39m: stream} \u001b[39mif\u001b[39;00m stream \u001b[39mis\u001b[39;00m \u001b[39mnot\u001b[39;00m \u001b[39mNone\u001b[39;00m \u001b[39melse\u001b[39;00m {}),\n\u001b[1;32m    437\u001b[0m     \u001b[39m*\u001b[39m\u001b[39m*\u001b[39mkwargs,\n\u001b[1;32m    438\u001b[0m }\n\u001b[0;32m--> 439\u001b[0m response \u001b[39m=\u001b[39m \u001b[39mself\u001b[39;49m\u001b[39m.\u001b[39;49mcompletion_with_retry(\n\u001b[1;32m    440\u001b[0m     messages\u001b[39m=\u001b[39;49mmessage_dicts, run_manager\u001b[39m=\u001b[39;49mrun_manager, \u001b[39m*\u001b[39;49m\u001b[39m*\u001b[39;49mparams\n\u001b[1;32m    441\u001b[0m )\n\u001b[1;32m    442\u001b[0m \u001b[39mreturn\u001b[39;00m \u001b[39mself\u001b[39m\u001b[39m.\u001b[39m_create_chat_result(response)\n",
      "File \u001b[0;32m~/anaconda3/envs/llm4/lib/python3.9/site-packages/langchain_community/chat_models/openai.py:356\u001b[0m, in \u001b[0;36mChatOpenAI.completion_with_retry\u001b[0;34m(self, run_manager, **kwargs)\u001b[0m\n\u001b[1;32m    354\u001b[0m \u001b[39m\u001b[39m\u001b[39m\"\"\"Use tenacity to retry the completion call.\"\"\"\u001b[39;00m\n\u001b[1;32m    355\u001b[0m \u001b[39mif\u001b[39;00m is_openai_v1():\n\u001b[0;32m--> 356\u001b[0m     \u001b[39mreturn\u001b[39;00m \u001b[39mself\u001b[39;49m\u001b[39m.\u001b[39;49mclient\u001b[39m.\u001b[39;49mcreate(\u001b[39m*\u001b[39;49m\u001b[39m*\u001b[39;49mkwargs)\n\u001b[1;32m    358\u001b[0m retry_decorator \u001b[39m=\u001b[39m _create_retry_decorator(\u001b[39mself\u001b[39m, run_manager\u001b[39m=\u001b[39mrun_manager)\n\u001b[1;32m    360\u001b[0m \u001b[39m@retry_decorator\u001b[39m\n\u001b[1;32m    361\u001b[0m \u001b[39mdef\u001b[39;00m \u001b[39m_completion_with_retry\u001b[39m(\u001b[39m*\u001b[39m\u001b[39m*\u001b[39mkwargs: Any) \u001b[39m-\u001b[39m\u001b[39m>\u001b[39m Any:\n",
      "File \u001b[0;32m~/anaconda3/envs/llm4/lib/python3.9/site-packages/openai/_utils/_utils.py:271\u001b[0m, in \u001b[0;36mrequired_args.<locals>.inner.<locals>.wrapper\u001b[0;34m(*args, **kwargs)\u001b[0m\n\u001b[1;32m    269\u001b[0m             msg \u001b[39m=\u001b[39m \u001b[39mf\u001b[39m\u001b[39m\"\u001b[39m\u001b[39mMissing required argument: \u001b[39m\u001b[39m{\u001b[39;00mquote(missing[\u001b[39m0\u001b[39m])\u001b[39m}\u001b[39;00m\u001b[39m\"\u001b[39m\n\u001b[1;32m    270\u001b[0m     \u001b[39mraise\u001b[39;00m \u001b[39mTypeError\u001b[39;00m(msg)\n\u001b[0;32m--> 271\u001b[0m \u001b[39mreturn\u001b[39;00m func(\u001b[39m*\u001b[39;49margs, \u001b[39m*\u001b[39;49m\u001b[39m*\u001b[39;49mkwargs)\n",
      "File \u001b[0;32m~/anaconda3/envs/llm4/lib/python3.9/site-packages/openai/resources/chat/completions.py:659\u001b[0m, in \u001b[0;36mCompletions.create\u001b[0;34m(self, messages, model, frequency_penalty, function_call, functions, logit_bias, logprobs, max_tokens, n, presence_penalty, response_format, seed, stop, stream, temperature, tool_choice, tools, top_logprobs, top_p, user, extra_headers, extra_query, extra_body, timeout)\u001b[0m\n\u001b[1;32m    608\u001b[0m \u001b[39m@required_args\u001b[39m([\u001b[39m\"\u001b[39m\u001b[39mmessages\u001b[39m\u001b[39m\"\u001b[39m, \u001b[39m\"\u001b[39m\u001b[39mmodel\u001b[39m\u001b[39m\"\u001b[39m], [\u001b[39m\"\u001b[39m\u001b[39mmessages\u001b[39m\u001b[39m\"\u001b[39m, \u001b[39m\"\u001b[39m\u001b[39mmodel\u001b[39m\u001b[39m\"\u001b[39m, \u001b[39m\"\u001b[39m\u001b[39mstream\u001b[39m\u001b[39m\"\u001b[39m])\n\u001b[1;32m    609\u001b[0m \u001b[39mdef\u001b[39;00m \u001b[39mcreate\u001b[39m(\n\u001b[1;32m    610\u001b[0m     \u001b[39mself\u001b[39m,\n\u001b[0;32m   (...)\u001b[0m\n\u001b[1;32m    657\u001b[0m     timeout: \u001b[39mfloat\u001b[39m \u001b[39m|\u001b[39m httpx\u001b[39m.\u001b[39mTimeout \u001b[39m|\u001b[39m \u001b[39mNone\u001b[39;00m \u001b[39m|\u001b[39m NotGiven \u001b[39m=\u001b[39m NOT_GIVEN,\n\u001b[1;32m    658\u001b[0m ) \u001b[39m-\u001b[39m\u001b[39m>\u001b[39m ChatCompletion \u001b[39m|\u001b[39m Stream[ChatCompletionChunk]:\n\u001b[0;32m--> 659\u001b[0m     \u001b[39mreturn\u001b[39;00m \u001b[39mself\u001b[39;49m\u001b[39m.\u001b[39;49m_post(\n\u001b[1;32m    660\u001b[0m         \u001b[39m\"\u001b[39;49m\u001b[39m/chat/completions\u001b[39;49m\u001b[39m\"\u001b[39;49m,\n\u001b[1;32m    661\u001b[0m         body\u001b[39m=\u001b[39;49mmaybe_transform(\n\u001b[1;32m    662\u001b[0m             {\n\u001b[1;32m    663\u001b[0m                 \u001b[39m\"\u001b[39;49m\u001b[39mmessages\u001b[39;49m\u001b[39m\"\u001b[39;49m: messages,\n\u001b[1;32m    664\u001b[0m                 \u001b[39m\"\u001b[39;49m\u001b[39mmodel\u001b[39;49m\u001b[39m\"\u001b[39;49m: model,\n\u001b[1;32m    665\u001b[0m                 \u001b[39m\"\u001b[39;49m\u001b[39mfrequency_penalty\u001b[39;49m\u001b[39m\"\u001b[39;49m: frequency_penalty,\n\u001b[1;32m    666\u001b[0m                 \u001b[39m\"\u001b[39;49m\u001b[39mfunction_call\u001b[39;49m\u001b[39m\"\u001b[39;49m: function_call,\n\u001b[1;32m    667\u001b[0m                 \u001b[39m\"\u001b[39;49m\u001b[39mfunctions\u001b[39;49m\u001b[39m\"\u001b[39;49m: functions,\n\u001b[1;32m    668\u001b[0m                 \u001b[39m\"\u001b[39;49m\u001b[39mlogit_bias\u001b[39;49m\u001b[39m\"\u001b[39;49m: logit_bias,\n\u001b[1;32m    669\u001b[0m                 \u001b[39m\"\u001b[39;49m\u001b[39mlogprobs\u001b[39;49m\u001b[39m\"\u001b[39;49m: logprobs,\n\u001b[1;32m    670\u001b[0m                 \u001b[39m\"\u001b[39;49m\u001b[39mmax_tokens\u001b[39;49m\u001b[39m\"\u001b[39;49m: max_tokens,\n\u001b[1;32m    671\u001b[0m                 \u001b[39m\"\u001b[39;49m\u001b[39mn\u001b[39;49m\u001b[39m\"\u001b[39;49m: n,\n\u001b[1;32m    672\u001b[0m                 \u001b[39m\"\u001b[39;49m\u001b[39mpresence_penalty\u001b[39;49m\u001b[39m\"\u001b[39;49m: presence_penalty,\n\u001b[1;32m    673\u001b[0m                 \u001b[39m\"\u001b[39;49m\u001b[39mresponse_format\u001b[39;49m\u001b[39m\"\u001b[39;49m: response_format,\n\u001b[1;32m    674\u001b[0m                 \u001b[39m\"\u001b[39;49m\u001b[39mseed\u001b[39;49m\u001b[39m\"\u001b[39;49m: seed,\n\u001b[1;32m    675\u001b[0m                 \u001b[39m\"\u001b[39;49m\u001b[39mstop\u001b[39;49m\u001b[39m\"\u001b[39;49m: stop,\n\u001b[1;32m    676\u001b[0m                 \u001b[39m\"\u001b[39;49m\u001b[39mstream\u001b[39;49m\u001b[39m\"\u001b[39;49m: stream,\n\u001b[1;32m    677\u001b[0m                 \u001b[39m\"\u001b[39;49m\u001b[39mtemperature\u001b[39;49m\u001b[39m\"\u001b[39;49m: temperature,\n\u001b[1;32m    678\u001b[0m                 \u001b[39m\"\u001b[39;49m\u001b[39mtool_choice\u001b[39;49m\u001b[39m\"\u001b[39;49m: tool_choice,\n\u001b[1;32m    679\u001b[0m                 \u001b[39m\"\u001b[39;49m\u001b[39mtools\u001b[39;49m\u001b[39m\"\u001b[39;49m: tools,\n\u001b[1;32m    680\u001b[0m                 \u001b[39m\"\u001b[39;49m\u001b[39mtop_logprobs\u001b[39;49m\u001b[39m\"\u001b[39;49m: top_logprobs,\n\u001b[1;32m    681\u001b[0m                 \u001b[39m\"\u001b[39;49m\u001b[39mtop_p\u001b[39;49m\u001b[39m\"\u001b[39;49m: top_p,\n\u001b[1;32m    682\u001b[0m                 \u001b[39m\"\u001b[39;49m\u001b[39muser\u001b[39;49m\u001b[39m\"\u001b[39;49m: user,\n\u001b[1;32m    683\u001b[0m             },\n\u001b[1;32m    684\u001b[0m             completion_create_params\u001b[39m.\u001b[39;49mCompletionCreateParams,\n\u001b[1;32m    685\u001b[0m         ),\n\u001b[1;32m    686\u001b[0m         options\u001b[39m=\u001b[39;49mmake_request_options(\n\u001b[1;32m    687\u001b[0m             extra_headers\u001b[39m=\u001b[39;49mextra_headers, extra_query\u001b[39m=\u001b[39;49mextra_query, extra_body\u001b[39m=\u001b[39;49mextra_body, timeout\u001b[39m=\u001b[39;49mtimeout\n\u001b[1;32m    688\u001b[0m         ),\n\u001b[1;32m    689\u001b[0m         cast_to\u001b[39m=\u001b[39;49mChatCompletion,\n\u001b[1;32m    690\u001b[0m         stream\u001b[39m=\u001b[39;49mstream \u001b[39mor\u001b[39;49;00m \u001b[39mFalse\u001b[39;49;00m,\n\u001b[1;32m    691\u001b[0m         stream_cls\u001b[39m=\u001b[39;49mStream[ChatCompletionChunk],\n\u001b[1;32m    692\u001b[0m     )\n",
      "File \u001b[0;32m~/anaconda3/envs/llm4/lib/python3.9/site-packages/openai/_base_client.py:1200\u001b[0m, in \u001b[0;36mSyncAPIClient.post\u001b[0;34m(self, path, cast_to, body, options, files, stream, stream_cls)\u001b[0m\n\u001b[1;32m   1186\u001b[0m \u001b[39mdef\u001b[39;00m \u001b[39mpost\u001b[39m(\n\u001b[1;32m   1187\u001b[0m     \u001b[39mself\u001b[39m,\n\u001b[1;32m   1188\u001b[0m     path: \u001b[39mstr\u001b[39m,\n\u001b[0;32m   (...)\u001b[0m\n\u001b[1;32m   1195\u001b[0m     stream_cls: \u001b[39mtype\u001b[39m[_StreamT] \u001b[39m|\u001b[39m \u001b[39mNone\u001b[39;00m \u001b[39m=\u001b[39m \u001b[39mNone\u001b[39;00m,\n\u001b[1;32m   1196\u001b[0m ) \u001b[39m-\u001b[39m\u001b[39m>\u001b[39m ResponseT \u001b[39m|\u001b[39m _StreamT:\n\u001b[1;32m   1197\u001b[0m     opts \u001b[39m=\u001b[39m FinalRequestOptions\u001b[39m.\u001b[39mconstruct(\n\u001b[1;32m   1198\u001b[0m         method\u001b[39m=\u001b[39m\u001b[39m\"\u001b[39m\u001b[39mpost\u001b[39m\u001b[39m\"\u001b[39m, url\u001b[39m=\u001b[39mpath, json_data\u001b[39m=\u001b[39mbody, files\u001b[39m=\u001b[39mto_httpx_files(files), \u001b[39m*\u001b[39m\u001b[39m*\u001b[39moptions\n\u001b[1;32m   1199\u001b[0m     )\n\u001b[0;32m-> 1200\u001b[0m     \u001b[39mreturn\u001b[39;00m cast(ResponseT, \u001b[39mself\u001b[39;49m\u001b[39m.\u001b[39;49mrequest(cast_to, opts, stream\u001b[39m=\u001b[39;49mstream, stream_cls\u001b[39m=\u001b[39;49mstream_cls))\n",
      "File \u001b[0;32m~/anaconda3/envs/llm4/lib/python3.9/site-packages/openai/_base_client.py:889\u001b[0m, in \u001b[0;36mSyncAPIClient.request\u001b[0;34m(self, cast_to, options, remaining_retries, stream, stream_cls)\u001b[0m\n\u001b[1;32m    880\u001b[0m \u001b[39mdef\u001b[39;00m \u001b[39mrequest\u001b[39m(\n\u001b[1;32m    881\u001b[0m     \u001b[39mself\u001b[39m,\n\u001b[1;32m    882\u001b[0m     cast_to: Type[ResponseT],\n\u001b[0;32m   (...)\u001b[0m\n\u001b[1;32m    887\u001b[0m     stream_cls: \u001b[39mtype\u001b[39m[_StreamT] \u001b[39m|\u001b[39m \u001b[39mNone\u001b[39;00m \u001b[39m=\u001b[39m \u001b[39mNone\u001b[39;00m,\n\u001b[1;32m    888\u001b[0m ) \u001b[39m-\u001b[39m\u001b[39m>\u001b[39m ResponseT \u001b[39m|\u001b[39m _StreamT:\n\u001b[0;32m--> 889\u001b[0m     \u001b[39mreturn\u001b[39;00m \u001b[39mself\u001b[39;49m\u001b[39m.\u001b[39;49m_request(\n\u001b[1;32m    890\u001b[0m         cast_to\u001b[39m=\u001b[39;49mcast_to,\n\u001b[1;32m    891\u001b[0m         options\u001b[39m=\u001b[39;49moptions,\n\u001b[1;32m    892\u001b[0m         stream\u001b[39m=\u001b[39;49mstream,\n\u001b[1;32m    893\u001b[0m         stream_cls\u001b[39m=\u001b[39;49mstream_cls,\n\u001b[1;32m    894\u001b[0m         remaining_retries\u001b[39m=\u001b[39;49mremaining_retries,\n\u001b[1;32m    895\u001b[0m     )\n",
      "File \u001b[0;32m~/anaconda3/envs/llm4/lib/python3.9/site-packages/openai/_base_client.py:942\u001b[0m, in \u001b[0;36mSyncAPIClient._request\u001b[0;34m(self, cast_to, options, remaining_retries, stream, stream_cls)\u001b[0m\n\u001b[1;32m    939\u001b[0m log\u001b[39m.\u001b[39mdebug(\u001b[39m\"\u001b[39m\u001b[39mEncountered Exception\u001b[39m\u001b[39m\"\u001b[39m, exc_info\u001b[39m=\u001b[39m\u001b[39mTrue\u001b[39;00m)\n\u001b[1;32m    941\u001b[0m \u001b[39mif\u001b[39;00m retries \u001b[39m>\u001b[39m \u001b[39m0\u001b[39m:\n\u001b[0;32m--> 942\u001b[0m     \u001b[39mreturn\u001b[39;00m \u001b[39mself\u001b[39;49m\u001b[39m.\u001b[39;49m_retry_request(\n\u001b[1;32m    943\u001b[0m         options,\n\u001b[1;32m    944\u001b[0m         cast_to,\n\u001b[1;32m    945\u001b[0m         retries,\n\u001b[1;32m    946\u001b[0m         stream\u001b[39m=\u001b[39;49mstream,\n\u001b[1;32m    947\u001b[0m         stream_cls\u001b[39m=\u001b[39;49mstream_cls,\n\u001b[1;32m    948\u001b[0m         response_headers\u001b[39m=\u001b[39;49m\u001b[39mNone\u001b[39;49;00m,\n\u001b[1;32m    949\u001b[0m     )\n\u001b[1;32m    951\u001b[0m log\u001b[39m.\u001b[39mdebug(\u001b[39m\"\u001b[39m\u001b[39mRaising connection error\u001b[39m\u001b[39m\"\u001b[39m)\n\u001b[1;32m    952\u001b[0m \u001b[39mraise\u001b[39;00m APIConnectionError(request\u001b[39m=\u001b[39mrequest) \u001b[39mfrom\u001b[39;00m \u001b[39merr\u001b[39;00m\n",
      "File \u001b[0;32m~/anaconda3/envs/llm4/lib/python3.9/site-packages/openai/_base_client.py:1013\u001b[0m, in \u001b[0;36mSyncAPIClient._retry_request\u001b[0;34m(self, options, cast_to, remaining_retries, response_headers, stream, stream_cls)\u001b[0m\n\u001b[1;32m   1009\u001b[0m \u001b[39m# In a synchronous context we are blocking the entire thread. Up to the library user to run the client in a\u001b[39;00m\n\u001b[1;32m   1010\u001b[0m \u001b[39m# different thread if necessary.\u001b[39;00m\n\u001b[1;32m   1011\u001b[0m time\u001b[39m.\u001b[39msleep(timeout)\n\u001b[0;32m-> 1013\u001b[0m \u001b[39mreturn\u001b[39;00m \u001b[39mself\u001b[39;49m\u001b[39m.\u001b[39;49m_request(\n\u001b[1;32m   1014\u001b[0m     options\u001b[39m=\u001b[39;49moptions,\n\u001b[1;32m   1015\u001b[0m     cast_to\u001b[39m=\u001b[39;49mcast_to,\n\u001b[1;32m   1016\u001b[0m     remaining_retries\u001b[39m=\u001b[39;49mremaining,\n\u001b[1;32m   1017\u001b[0m     stream\u001b[39m=\u001b[39;49mstream,\n\u001b[1;32m   1018\u001b[0m     stream_cls\u001b[39m=\u001b[39;49mstream_cls,\n\u001b[1;32m   1019\u001b[0m )\n",
      "File \u001b[0;32m~/anaconda3/envs/llm4/lib/python3.9/site-packages/openai/_base_client.py:942\u001b[0m, in \u001b[0;36mSyncAPIClient._request\u001b[0;34m(self, cast_to, options, remaining_retries, stream, stream_cls)\u001b[0m\n\u001b[1;32m    939\u001b[0m log\u001b[39m.\u001b[39mdebug(\u001b[39m\"\u001b[39m\u001b[39mEncountered Exception\u001b[39m\u001b[39m\"\u001b[39m, exc_info\u001b[39m=\u001b[39m\u001b[39mTrue\u001b[39;00m)\n\u001b[1;32m    941\u001b[0m \u001b[39mif\u001b[39;00m retries \u001b[39m>\u001b[39m \u001b[39m0\u001b[39m:\n\u001b[0;32m--> 942\u001b[0m     \u001b[39mreturn\u001b[39;00m \u001b[39mself\u001b[39;49m\u001b[39m.\u001b[39;49m_retry_request(\n\u001b[1;32m    943\u001b[0m         options,\n\u001b[1;32m    944\u001b[0m         cast_to,\n\u001b[1;32m    945\u001b[0m         retries,\n\u001b[1;32m    946\u001b[0m         stream\u001b[39m=\u001b[39;49mstream,\n\u001b[1;32m    947\u001b[0m         stream_cls\u001b[39m=\u001b[39;49mstream_cls,\n\u001b[1;32m    948\u001b[0m         response_headers\u001b[39m=\u001b[39;49m\u001b[39mNone\u001b[39;49;00m,\n\u001b[1;32m    949\u001b[0m     )\n\u001b[1;32m    951\u001b[0m log\u001b[39m.\u001b[39mdebug(\u001b[39m\"\u001b[39m\u001b[39mRaising connection error\u001b[39m\u001b[39m\"\u001b[39m)\n\u001b[1;32m    952\u001b[0m \u001b[39mraise\u001b[39;00m APIConnectionError(request\u001b[39m=\u001b[39mrequest) \u001b[39mfrom\u001b[39;00m \u001b[39merr\u001b[39;00m\n",
      "File \u001b[0;32m~/anaconda3/envs/llm4/lib/python3.9/site-packages/openai/_base_client.py:1013\u001b[0m, in \u001b[0;36mSyncAPIClient._retry_request\u001b[0;34m(self, options, cast_to, remaining_retries, response_headers, stream, stream_cls)\u001b[0m\n\u001b[1;32m   1009\u001b[0m \u001b[39m# In a synchronous context we are blocking the entire thread. Up to the library user to run the client in a\u001b[39;00m\n\u001b[1;32m   1010\u001b[0m \u001b[39m# different thread if necessary.\u001b[39;00m\n\u001b[1;32m   1011\u001b[0m time\u001b[39m.\u001b[39msleep(timeout)\n\u001b[0;32m-> 1013\u001b[0m \u001b[39mreturn\u001b[39;00m \u001b[39mself\u001b[39;49m\u001b[39m.\u001b[39;49m_request(\n\u001b[1;32m   1014\u001b[0m     options\u001b[39m=\u001b[39;49moptions,\n\u001b[1;32m   1015\u001b[0m     cast_to\u001b[39m=\u001b[39;49mcast_to,\n\u001b[1;32m   1016\u001b[0m     remaining_retries\u001b[39m=\u001b[39;49mremaining,\n\u001b[1;32m   1017\u001b[0m     stream\u001b[39m=\u001b[39;49mstream,\n\u001b[1;32m   1018\u001b[0m     stream_cls\u001b[39m=\u001b[39;49mstream_cls,\n\u001b[1;32m   1019\u001b[0m )\n",
      "File \u001b[0;32m~/anaconda3/envs/llm4/lib/python3.9/site-packages/openai/_base_client.py:952\u001b[0m, in \u001b[0;36mSyncAPIClient._request\u001b[0;34m(self, cast_to, options, remaining_retries, stream, stream_cls)\u001b[0m\n\u001b[1;32m    942\u001b[0m         \u001b[39mreturn\u001b[39;00m \u001b[39mself\u001b[39m\u001b[39m.\u001b[39m_retry_request(\n\u001b[1;32m    943\u001b[0m             options,\n\u001b[1;32m    944\u001b[0m             cast_to,\n\u001b[0;32m   (...)\u001b[0m\n\u001b[1;32m    948\u001b[0m             response_headers\u001b[39m=\u001b[39m\u001b[39mNone\u001b[39;00m,\n\u001b[1;32m    949\u001b[0m         )\n\u001b[1;32m    951\u001b[0m     log\u001b[39m.\u001b[39mdebug(\u001b[39m\"\u001b[39m\u001b[39mRaising connection error\u001b[39m\u001b[39m\"\u001b[39m)\n\u001b[0;32m--> 952\u001b[0m     \u001b[39mraise\u001b[39;00m APIConnectionError(request\u001b[39m=\u001b[39mrequest) \u001b[39mfrom\u001b[39;00m \u001b[39merr\u001b[39;00m\n\u001b[1;32m    954\u001b[0m log\u001b[39m.\u001b[39mdebug(\n\u001b[1;32m    955\u001b[0m     \u001b[39m'\u001b[39m\u001b[39mHTTP Request: \u001b[39m\u001b[39m%s\u001b[39;00m\u001b[39m \u001b[39m\u001b[39m%s\u001b[39;00m\u001b[39m \u001b[39m\u001b[39m\"\u001b[39m\u001b[39m%i\u001b[39;00m\u001b[39m \u001b[39m\u001b[39m%s\u001b[39;00m\u001b[39m\"\u001b[39m\u001b[39m'\u001b[39m, request\u001b[39m.\u001b[39mmethod, request\u001b[39m.\u001b[39murl, response\u001b[39m.\u001b[39mstatus_code, response\u001b[39m.\u001b[39mreason_phrase\n\u001b[1;32m    956\u001b[0m )\n\u001b[1;32m    958\u001b[0m \u001b[39mtry\u001b[39;00m:\n",
      "\u001b[0;31mAPIConnectionError\u001b[0m: Connection error."
     ]
    }
   ],
   "source": [
    "ai_message = chat(messages)"
   ]
  },
  {
   "cell_type": "code",
   "execution_count": null,
   "metadata": {},
   "outputs": [],
   "source": []
  }
 ],
 "metadata": {
  "kernelspec": {
   "display_name": "llm4",
   "language": "python",
   "name": "llm4"
  },
  "language_info": {
   "codemirror_mode": {
    "name": "ipython",
    "version": 3
   },
   "file_extension": ".py",
   "mimetype": "text/x-python",
   "name": "python",
   "nbconvert_exporter": "python",
   "pygments_lexer": "ipython3",
   "version": "3.9.18"
  },
  "orig_nbformat": 4
 },
 "nbformat": 4,
 "nbformat_minor": 2
}
